<?xml version="1.0"?>
<robot xmlns:xacro="http://www.ros.org/wiki/xacro" name="gofa">

	<!-- GoFa color -->
	<material name="gofa_color">
		<color rgba="0.792156862745098 0.819607843137255 0.933333333333333 1"/>
	</material>

	<!-- VC macro -->
	<xacro:macro name="VC" params="suffix">
		<origin xyz="0 0 0" rpy="0 0 0"/>
		<geometry>
			<mesh filename="package://robots_description/meshes/Gofa/${suffix}.STL"/>
		</geometry>
	</xacro:macro>

	<!-- visual and collision macro -->
	<xacro:macro name="visual_plus_collision" params="v_p_c_name">
		<visual>
			<xacro:VC suffix="${v_p_c_name}"/>
			<material name="gofa_color"/>
		</visual>
		<collision>
			<xacro:VC suffix="${v_p_c_name}"/>
		</collision>
	</xacro:macro>

	<!-- Internal link names -->
	<xacro:arg name="base_link_name" 	default="base"/>
	<xacro:arg name="1st_link_name" 	default="L1"/>
	<xacro:arg name="2nd_link_name" 	default="L2"/>
	<xacro:arg name="3rd_link_name" 	default="L3"/>
	<xacro:arg name="4th_link_name" 	default="L4"/>
	<xacro:arg name="5th_link_name" 	default="L5"/>
	<xacro:arg name="6th_link_name" 	default="L6"/>

	<!-- GoFa URDF model -->
	<xacro:macro name="gofa" params="parent child *origin">
		<joint name="${parent}_to_$(arg base_link_name)" type="fixed">
			<xacro:insert_block name="origin"/>
			<parent link="${parent}"/>
			<child link="$(arg base_link_name)"/>
		</joint>
		<link name="$(arg base_link_name)">
			<inertial>
				<origin xyz="-0.0012013793465437 -0.000175191786981708 0.0862146007385352" rpy="0 0 0"/>
				<mass value="3.50083457958494"/>
				<inertia ixx="0.0153015257917955" ixy="-6.40155032892694E-05" ixz="-0.000276708687772683" 
						 iyy="0.0159333503953857" iyz="-3.98029144780725E-05" izz="0.0112162302268266"/>
			</inertial>
			<xacro:visual_plus_collision v_p_c_name="$(arg base_link_name)"/>
		</link>
		<link name="$(arg 1st_link_name)">
			<inertial>
				<origin xyz="2.08682453325091E-06 0.0103608399967513 0.0705307203199506" rpy="0 0 0"/>
				<mass value="2.76743491139404"/>
				<inertia ixx="0.0115158625894577" ixy="6.37197693598838E-08" ixz="5.98954393680154E-09" 
						 iyy="0.006494848329231" iyz="-0.000196668400316843" izz="0.0109446835358581"/>
			</inertial>
			<xacro:visual_plus_collision v_p_c_name="$(arg 1st_link_name)"/>
		</link>
		<joint name="J1" type="revolute">
			<origin xyz="0 0 0.1875" rpy="0 0 0"/>
			<parent link="$(arg base_link_name)"/>
			<child link="$(arg 1st_link_name)"/>
			<axis xyz="0 0 1"/>
			<limit effort="0" lower="${radians(-180)}" upper="${radians(180)}" velocity="${radians(125)}"/>
		</joint>
		<link name="$(arg 2nd_link_name)">
			<inertial>
				<origin xyz="1.34018352211628E-06 -0.0500118376116071 0.222001399322246" rpy="0 0 0"/>
				<mass value="4.28904168670464"/>
				<inertia ixx="0.130524729873898" ixy="1.31811857134115E-07" ixz="1.99022457670482E-06" 
						 iyy="0.133278449324229" iyz="-4.48622200366709E-07" izz="0.00669457974697178"/>
			</inertial>
			<xacro:visual_plus_collision v_p_c_name="$(arg 2nd_link_name)"/>
		</link>
		<joint name="J2" type="revolute">
			<origin xyz="0 -0.085 0.0775" rpy="0 0 0"/>
			<parent link="$(arg 1st_link_name)"/>
			<child link="$(arg 2nd_link_name)"/>
			<axis xyz="0 1 0"/>
			<limit effort="0" lower="${radians(-180)}" upper="${radians(180)}" velocity="${radians(125)}"/>
		</joint>
		<link name="$(arg 3rd_link_name)">
			<inertial>
				<origin xyz="0.0128129281453599 0.0944171780907046 0.0247427540642403" rpy="0 0 0"/>
				<mass value="3.38333107992875"/>
				<inertia ixx="0.0175626138728642" ixy="0.000364866179108744" ixz="-0.00318670290285352" 
						 iyy="0.0140230068919562" iyz="0.000704668055158407" izz="0.013275205067567"/>
			</inertial>
			<xacro:visual_plus_collision v_p_c_name="$(arg 3rd_link_name)"/>
		</link>
		<joint name="J3" type="revolute">
			<origin xyz="0 -0.00100000000000007 0.444" rpy="0 0 0"/>
			<parent link="$(arg 2nd_link_name)"/>
			<child link="$(arg 3rd_link_name)"/>
			<axis xyz="0 1 0"/>
			<limit effort="0" lower="${radians(-225)}" upper="${radians(85)}" velocity="${radians(140)}"/>
		</joint>
		<link name="$(arg 4th_link_name)">
			<inertial>
				<origin xyz="0.160558561602322 0.041976811408979 -2.36623354021859E-07" rpy="0 0 0"/>
				<mass value="2.77857535641324"/>
				<inertia ixx="0.00881683095901354" ixy="-0.010746260580237" ixz="1.2899930119841E-07" 
						 iyy="0.0340754175571832" iyz="3.96362791626429E-08" izz="0.0389358932156922"/>
			</inertial>
			<xacro:visual_plus_collision v_p_c_name="$(arg 4th_link_name)"/>
		</link>
		<joint name="J4" type="revolute">
			<origin xyz="0.096 0.0860000000000001 0.11" rpy="0 0 0"/>
			<parent link="$(arg 3rd_link_name)"/>
			<child link="$(arg 4th_link_name)"/>
			<axis xyz="1 0 0"/>
			<limit effort="0" lower="${radians(-180)}" upper="${radians(180)}" velocity="${radians(200)}"/>
		</joint>
		<link name="$(arg 5th_link_name)">
			<inertial>
				<origin xyz="-0.0147152361879962 -0.0785646469392633 0.0427558021601431" rpy="0 0 0"/>
				<mass value="3.01105814739001"/>
				<inertia ixx="0.0114597336686444" ixy="0.000180094704361231" ixz="0.00165207280226761" 
						 iyy="0.013561904467501" iyz="-0.000525272443978826" izz="0.0108480119549914"/>
			</inertial>
			<xacro:visual_plus_collision v_p_c_name="$(arg 5th_link_name)"/>
		</link>
		<joint name="J5" type="revolute">
			<origin xyz="0.374 0.0744999999999998 0" rpy="0 0 0"/>
			<parent link="$(arg 4th_link_name)"/>
			<child link="$(arg 5th_link_name)"/>
			<axis xyz="0 1 0"/>
			<limit effort="0" lower="${radians(-180)}" upper="${radians(180)}" velocity="${radians(200)}"/>
		</joint>
		<link name="$(arg 6th_link_name)">
			<inertial>
				<origin xyz="0.0137506852604966 0.000239804131398652 -0.000341962798940165" rpy="0 0 0"/>
				<mass value="0.146500988015653"/>
				<inertia ixx="0.000128977630055306" ixy="-8.7622752508613E-08" ixz="1.18851551870012E-07" 
						 iyy="7.61118177829087E-05" iyz="-6.49821554399679E-07" izz="7.65022909768016E-05"/>
			</inertial>
			<xacro:visual_plus_collision v_p_c_name="$(arg 6th_link_name)"/>
		</link>
		<joint name="J6" type="revolute">
			<origin xyz="0.0679999999999995 -0.0744999999999998 0.0800000000000003" rpy="0 0 0"/>
			<parent link="$(arg 5th_link_name)"/>
			<child link="$(arg 6th_link_name)"/>
			<axis xyz="1 0 0"/>
			<limit effort="0" lower="${radians(-180)}" upper="${radians(180)}" velocity="${radians(200)}"/>
		</joint>
		<link name="${child}">
		</link>
		<joint name="$(arg 6th_link_name)_to_${child}" type="fixed">
			<origin xyz="0.033599981 0 0" rpy="0 ${radians(90)} 0"/>
			<parent link="$(arg 6th_link_name)"/>
			<child link="${child}"/>
		</joint>
	</xacro:macro>

</robot>
